Workbook

Sheet products
A1: id | B1: published | C1: parent | D1: template | E1: article | G1: pagetitle | H1: description | I1: price | J1: made_in | K1: weight | L1: alias | M1: content | N1: menuindex | O1: market_image | P1: market_title | Q1: market_description | R1: pole1 | S1: pole2 | T1: pole3 | U1: pole4 | V1: pole5 | W1: brend | X1: koncern | Y1: chastota | Z1: original | AA1: sosok | AB1: number2 | AC1: images | AD1: remK | AE1: tipP | AF1: meta_keywords | AG1: meta_description
A2: 302522 | B2: 1 | C2: 8253 | D2: 20 | E2: 51839114 | F2: =VLOOKUP(E2,Лист1!A1:A306,1,FALSE) -> 51839114 | G2: Датчик давления в шине BH Sens ( Huf ) 51839114 для Fiat/Alfa/Chrysler/Dodge/Jeep | H2: Покупайте датчик давления в шине BH Sens ( Huf ) 51839114 для Fiat/Alfa/Chrysler/Dodge/Jeep по выгодным ценам | Большой выбор датчиков давления в шине | Осуществляем доставку на всей территории РФ | I2: 3250 | J2: Германия | K2: 30 | L2: dk-datchik-davlenia-v-shinah-51839114-8 | M2: <p>Датчик давления в шинах, номер по каталогу 51839114, передает сигналы с помощью радиоканала. Рабочая частота - 433МГц. Компания производитель <a href="https://alltpms.ru/proizvoditeli-sistem-tpms/beru"> BH Sens ( Huf ) </a>. Страна производства - Германия. Устройства предназначены для установки в колеса автомобилей, выпускаемых концерном Fiat/Alfa/Chrysler/Dodge/Jeep.</p><p></p><p> При условии установки на специализированных СТО, срок службы устройства составляет до 7 лет.</p><p>Конструктивные особенности данного датчика гарантируют его полную совместимость с системами авто концерна Fiat/Alfa/Chrysler/Dodge/Jeep. Датчик поставляется в комплекте с ниппелем, что заметно облегчает установку и не требует покупки дополнительных деталей. Материал ниппеля - металл. После установки датчик 51839114 требует привязки к авто. Привязка производится по методике <a href="https://alltpms.ru/katalog/privyazka/privyazka-4">«Автоматическая привязка»</a> (Карточка привязки).</p> | N2: 78 | O2: /market/HUF1410.jpg | P2: Датчик давления в шине BH Sens ( Huf ) 51839114 для Fiat/Alfa/Chrysler/Dodge/Jeep | Q2: Датчик давления в шине BH Sens ( Huf ) 51839114 для Fiat/Alfa/Chrysler/Dodge/Jeep | R2: Доставка от 1 шт. без предоплаты, Гарантия 2 года | S2: 0 | T2: 1 | U2: 51839114-8 | V2: 5054208002059 | W2: 622 | X2: Fiat/Alfa/Chrysler/Dodge/Jeep | Y2: 433 | Z2: no | AA2: Clamp-in | AB2: 4054, TX-S138, TPS0138, 9014-4054, 9015-4054, 1210-4054, 2210-4054, 2200-4054, 1400-4054, 1401-4054, 4040-4054, 4041-4054, 590914-4054, 590918-4054, 4054PFR, 4054PFM, 4054PVM | AC2: HUF1400-1.JPG||HUF1400-2.JPG||HUF1400-3.JPG||HUF1400-4.JPG||HUF1400-5.JPG||HUF1400-6.JPG||HUF1400-7.JPG||HUF1400-8.JPG||HUF1400-9.JPG||HUF1400-10.JPG | AD2: 229||92867||241||244||48032 | AE2: 586 | AG2: Покупайте датчик давления в шине BH Sens ( Huf ) 51839114 для Fiat/Alfa/Chrysler/Dodge/Jeep по выгодным ценам | Большой выбор датчиков давления в шине | Осуществляем доставку на всей территории РФ
A3: 302529 | B3: 1 | C3: 8253 | D3: 20 | E3: 36106874829 | F3: =VLOOKUP(E3,Лист1!A1:A306,1,FALSE) -> 36106874829 | G3: Датчик давления в шине для BMW 36106874829 Оригинал | H3: Купить по низкой цене оригинальный датчик давления в шинах для BMW 36106874829 с доставкой по Москве или России. | I3: 8250 | J3: Германия | K3: 30 | L3: dk-datchik-davlenia-v-shinah-36106790054-20 | M3: <p>Датчик, каталожный номер 36106874829. Передача данных производится посредством радиосигнала. Частота работы - 433МГц. Для автомобилей BMW. Страна-производитель - Германия.</p><p> Срок службы устройства варьируется и может достигать 7 лет. Данный показатель во многом зависит от интенсивности использования авто и условий его эксплуатации.</p><p> Конструктивные особенности датчика позволяют использовать его на большинстве марок авто производства BMW. Комплект поставки – датчик и ниппель. Материал ниппеля - металл. Комплект полностью готов к установке. Данный датчик, номер 36106874829 требует привязки к системе автомобиля. Для этого используется процедура <a href="https://alltpms.ru/katalog/privyazka/privyazka-4">«Автоматизированная привязка»</a> (Карточка привязки).</p> | N3: 80 | O3: /market/BMW829.jpg | P3: Датчик давления в шине для BMW 36106874829 Оригинал | Q3: Датчик давления в шине для BMW 36106874829 Оригинал | R3: Доставка от 1 шт. без предоплаты, Гарантия 2 года | S3: 0 | T3: 0 | U3: 36106790054-20 | V3: 5054208002066 | W3: 622 | X3: BMW | Y3: 433 | Z3: yes | AA3: Clamp-in | AB3: 36106790054, 36106856227, 4010, 550-1912, TX-S005L/R, TPS0005L/R, ECR0010, RDE012V21, 9014-4010, 9015-4010, 1210-4010, 2210-4010, 2200-4010, 1400-4010, 1401-4010, 4040-4010, 4041-4010, 590914-4010, 590918-4010, 4010PFR, 4010PFM, 4010PVM, 4040-RDE012, 4041-RDE012, RDE012PVM, RDE012PFR, RDE012PVM, RDE012PFR | AC3: 36106790054-1.JPG||36106790054-2.JPG||36106790054-3.JPG||36106790054-4.JPG||36106790054-5.JPG||36106790054-6.JPG||36106790054-7.JPG||36106790054-8.JPG||36106790054-9.JPG||36106790054-10.JPG | AD3: 229||92867||241||244||48032 | AE3: 588 | AF3: BMW BH Sens ( Huf ) 36106874829 36106790054, 36106856227, 4010, 550-1912, TX-S005L/R, TPS0005L/R, ECR0010, RDE012V21, 9014-4010, 9015-4010, 1210-4010, 2210-4010, 2200-4010, 1400-4010, 1401-4010, 4040-4010, 4041-4010, 590914-4010, 590918-4010, 4010PFR, 4010PFM, 4010PVM, 4040-RDE012, 4041-RDE012, RDE012PVM, RDE012PFR, RDE012PVM, RDE012PFR 36106790054, 36106856227, 4010, 5501912, TXS005L/R, TPS0005L/R, ECR0010, RDE012V21, 90144010, 90154010, 12104010, 22104010, 22004010, 14004010, 14014010, 40404010, 40414010, 5909144010, 5909184010, 4010PFR, 4010PFM, 4010PVM, 4040RDE012, 4041RDE012, RDE012PVM, RDE012PFR, RDE012PVM, RDE012PFR Оригинал | AG3: Купить оригинальный датчик давления в шине для BMW 36106874829 в Москве с доставкой. Цена от производителя. Большой выбор датчиков. Гарантия.
A4: 302530 | B4: 1 | C4: 8253 | D4: 20 | E4: 36106874829 | F4: =VLOOKUP(E4,Лист1!A1:A306,1,FALSE) -> 36106874829 | G4: Датчик давления в шине BH Sens ( Huf ) 36106874829 для BMW (Black Edition) | H4: Покупайте датчик давления в шине BH Sens ( Huf ) 36106874829 для BMW (Black Edition) по выгодным ценам | Большой выбор датчиков давления в шине | Осуществляем доставку на всей территории РФ | I4: 4250 | J4: Германия | K4: 30 | L4: dk-datchik-davlenia-v-shinah-36106790054b-29 | M4: <p>Датчик, номер по каталогу запчастей 36106874829. Предназначен для контроля давления в шинах. Передача данных осуществляется посредством радиосигнала на частоте 433МГц. Компания производитель датчика - <a href="https://alltpms.ru/proizvoditeli-sistem-tpms/beru"> BH Sens ( Huf ) </a>. Место производства - Германия.</p><p>Правильно установленный датчик гарантировано проработает 7 лет. В каждом конкретном случае срок службы может изменяться. Он зависит от условий эксплуатации, длительности поездок, их частоты.</p><p>Предназначенный для установки в колеса автомобилей большинства моделей концерна BMW, датчик поставляется в комплекте с ниппелем. Покупатель получает комплектное устройство. После установки датчик 36106874829 активируется, используется метод <a href="https://alltpms.ru/katalog/privyazka/privyazka-4">«Автоматизированная привязка»</a> (Карточка привязки).</p> | N4: 82 | O4: /market/HUF4040B.jpg | P4: Датчик давления в шине BH Sens ( Huf ) 36106874829 для BMW (Black Edition) | Q4: Датчик давления в шине BH Sens ( Huf ) 36106874829 для BMW (Black Edition) | R4: Доставка от 1 шт. без предоплаты, Гарантия 2 года | S4: 0 | T4: 1 | U4: 36106790054b-29 | V4: 5054208002067 | W4: 622 | X4: BMW | Y4: 433 | Z4: no | AA4: Clamp-in | AB4: 36106790054, 36106856227, 4010, 550-1912, TX-S005L/R, TPS0005L/R, ECR0010, RDE012V21, 9014-4010, 9015-4010, 1210-4010, 2210-4010, 2200-4010, 1400-4010, 1401-4010, 4040-4010, 4041-4010, 590914-4010, 590918-4010, 4010PFR, 4010PFM, 4010PVM, 4040-RDE012, 4041-RDE012, RDE012PVM, RDE012PFR, RDE012PVM, RDE012PFR | AC4: HUF4040_B-1.JPG||HUF4040_B-2.JPG||HUF4040_B-3.JPG||HUF4040_B-4.JPG||HUF4040_B-5.JPG||HUF4040_B-6.JPG||HUF4040_B-7.JPG||HUF4040_B-8.JPG||HUF4040_B-9.JPG||HUF4040_B-10.JPG | AD4: 229||92867||241||244||48032 | AE4: 588 | AG4: Покупайте датчик давления в шине BH Sens ( Huf ) 36106874829 для BMW (Black Edition) по выгодным ценам | Большой выбор датчиков давления в шине | Осуществляем доставку на всей территории РФ
A5: 302531 | B5: 1 | C5: 8253 | D5: 20 | E5: 36106874829 | F5: =VLOOKUP(E5,Лист1!A1:A306,1,FALSE) -> 36106874829 | G5: Датчик давления в шине BH Sens (Huf, Германия) 36106874829 для BMW (Black Edition) | H5: Покупайте датчик давления в шине BH Sens (Huf, Германия) 36106874829 для BMW (Black Edition) по выгодным ценам | Большой выбор датчиков давления в шине | Осуществляем доставку на всей территории РФ | I5: 3750 | J5: Германия | K5: 30 | L5: dk-datchik-davlenia-v-shinah-36106790054b-19 | M5: <p>Датчик, номер по каталогу запчастей 36106874829. Предназначен для контроля давления в шинах. Передача данных осуществляется посредством радиосигнала на частоте 433МГц. Компания производитель датчика - <a href="https://alltpms.ru/proizvoditeli-sistem-tpms/beru"> BH Sens ( Huf ) </a>. Место производства - Германия.</p><p>Правильно установленный датчик гарантировано проработает 7 лет. В каждом конкретном случае срок службы может изменяться. Он зависит от условий эксплуатации, длительности поездок, их частоты.</p><p>Предназначенный для установки в колеса автомобилей большинства моделей концерна BMW, датчик поставляется в комплекте с ниппелем. Покупатель получает комплектное устройство. После установки датчик 36106874829 активируется, используется метод <a href="https://alltpms.ru/katalog/privyazka/privyazka-4">«Автоматизированная привязка»</a> (Карточка привязки).</p> | N5: 83 | O5: /market/HUF1410B.jpg | P5: Датчик давления в шине BH Sens ( Huf ) 36106874829 для BMW (Black Edition) | Q5: Датчик давления в шине BH Sens ( Huf ) 36106874829 для BMW (Black Edition) | R5: Доставка от 1 шт. без предоплаты, Гарантия 2 года | S5: 0 | T5: 1 | U5: 36106790054b-19 | V5: 5054208002068 | W5: 622 | X5: BMW | Y5: 433 | Z5: no | AA5: Clamp-in | AB5: 36106790054, 36106856227, 4010, 550-1912, TX-S005L/R, TPS0005L/R, ECR0010, RDE012V21, 9014-4010, 9015-4010, 1210-4010, 2210-4010, 2200-4010, 1400-4010, 1401-4010, 4040-4010, 4041-4010, 590914-4010, 590918-4010, 4010PFR, 4010PFM, 4010PVM, 4040-RDE012, 4041-RDE012, RDE012PVM, RDE012PFR, RDE012PVM, RDE012PFR | AC5: HUF1400_B-1.JPG||HUF1400_B-2.JPG||HUF1400_B-3.JPG||HUF1400_B-4.JPG||HUF1400_B-5.JPG||HUF1400_B-6.JPG||HUF1400_B-7.JPG||HUF1400_B-8.JPG||HUF1400_B-9.JPG||HUF1400_B-10.JPG | AD5: 229||92867||241||244||48032 | AE5: 588 | AG5: Покупайте датчик давления в шине BH Sens (Huf, Германия) 36106874829 для BMW (Black Edition) по выгодным ценам | Большой выбор датчиков давления в шине | Осуществляем доставку на всей территории РФ
A6: 302532 | B6: 1 | C6: 8253 | D6: 20 | E6: 36106874829 | F6: =VLOOKUP(E6,Лист1!A1:A306,1,FALSE) -> 36106874829 | G6: Датчик давления в шине BH Sens ( Huf ) 36106874829 для BMW | H6: Покупайте датчик давления в шине BH Sens ( Huf ) 36106874829 для BMW по выгодным ценам | Большой выбор датчиков давления в шине | Осуществляем доставку на всей территории РФ | I6: 3750 | J6: Германия | K6: 30 | L6: dk-datchik-davlenia-v-shinah-36106790054-29 | M6: <p>Датчик, номер по каталогу запчастей 36106874829. Предназначен для контроля давления в шинах. Передача данных осуществляется посредством радиосигнала на частоте 433МГц. Компания производитель датчика - <a href="https://alltpms.ru/proizvoditeli-sistem-tpms/beru"> BH Sens ( Huf ) </a>. Место производства - Германия.</p><p>Правильно установленный датчик гарантировано проработает 7 лет. В каждом конкретном случае срок службы может изменяться. Он зависит от условий эксплуатации, длительности поездок, их частоты.</p><p>Предназначенный для установки в колеса автомобилей большинства моделей концерна BMW, датчик поставляется в комплекте с ниппелем. Покупатель получает комплектное устройство. После установки датчик 36106874829 активируется, используется метод <a href="https://alltpms.ru/katalog/privyazka/privyazka-4">«Автоматизированная привязка»</a> (Карточка привязки).</p> | N6: 81 | O6: /market/HUF4040.jpg | P6: Датчик давления в шине BH Sens ( Huf ) 36106874829 для BMW | Q6: Датчик давления в шине BH Sens ( Huf ) 36106874829 для BMW | R6: Доставка от 1 шт. без предоплаты, Гарантия 2 года | S6: 0 | T6: 1 | U6: 36106790054-29 | V6: 5054208002069 | W6: 622 | X6: BMW | Y6: 433 | Z6: no | AA6: Clamp-in | AB6: 36106790054, 36106856227, 4010, 550-1912, TX-S005L/R, TPS0005L/R, ECR0010, RDE012V21, 9014-4010, 9015-4010, 1210-4010, 2210-4010, 2200-4010, 1400-4010, 1401-4010, 4040-4010, 4041-4010, 590914-4010, 590918-4010, 4010PFR, 4010PFM, 4010PVM, 4040-RDE012, 4041-RDE012, RDE012PVM, RDE012PFR, RDE012PVM, RDE012PFR | AC6: HUF4040-1.JPG||HUF4040-2.JPG||HUF4040-3.JPG||HUF4040-4.JPG||HUF4040-5.JPG||HUF4040-6.JPG||HUF4040-7.JPG||HUF4040-8.JPG||HUF4040-9.JPG||HUF4040-10.JPG | AD6: 229||92867||241||244||48032 | AE6: 588 | AG6: Покупайте датчик давления в шине BH Sens ( Huf ) 36106874829 для BMW по выгодным ценам | Большой выбор датчиков давления в шине | Осуществляем доставку на всей территории РФ
A7: 302533 | B7: 1 | C7: 8253 | D7: 20 | E7: 36106874829 | F7: =VLOOKUP(E7,Лист1!A1:A306,1,FALSE) -> 36106874829 | G7: Датчик давления в шине BH Sens (Huf, Германия) 36106874829 для BMW | H7: Покупайте датчик давления в шине BH Sens (Huf, Германия) 36106874829 для BMW по выгодным ценам | Большой выбор датчиков давления в шине | Осуществляем доставку на всей территории РФ | I7: 3250 | J7: Германия | K7: 30 | L7: dk-datchik-davlenia-v-shinah-36106790054-219 | M7: <p> Датчик давления в шинах. Предназначен для автомобилей BMW. Каталожный номер запчасти 36106874829. Компания производитель - <a href="https://alltpms.ru/proizvoditeli-sistem-tpms/beru"> BH Sens ( Huf ) </a>, Германия.</p><p></p><p>При условии соблюдения правил установки и эксплуатации, срок службы датчика варьируется в пределах от 7 до 8 лет. Срок нормальной работы зависит от условий эксплуатации.</p><p>Данный датчик полностью совместим с большинством моделей автомобилей концерна BMW. В продажу поступает комплект (датчик и ниппель). После установки требуется произвести привязку и активацию. Данные процедуры выполняются по методу <a href="https://alltpms.ru/katalog/privyazka/privyazka-4">«Автоматизированная привязка»</a> (Карточка привязки).</p> | N7: 84 | O7: /market/HUF1410.jpg | P7: Датчик давления в шине BH Sens ( Huf ) 36106874829 для BMW | Q7: Датчик давления в шине BH Sens ( Huf ) 36106874829 для BMW | R7: Доставка от 1 шт. без предоплаты, Гарантия 2 года | S7: 0 | T7: 1 | U7: 36106790054-219 | V7: 5054208002070 | W7: 622 | X7: BMW | Y7: 433 | Z7: no | AA7: Clamp-in | AB7: 36106790054, 36106856227, 4010, 550-1912, TX-S005L/R, TPS0005L/R, ECR0010, RDE012V21, 9014-4010, 9015-4010, 1210-4010, 2210-4010, 2200-4010, 1400-4010, 1401-4010, 4040-4010, 4041-4010, 590914-4010, 590918-4010, 4010PFR, 4010PFM, 4010PVM, 4040-RDE012, 4041-RDE012, RDE012PVM, RDE012PFR, RDE012PVM, RDE012PFR | AC7: HUF1400-1.JPG||HUF1400-2.JPG||HUF1400-3.JPG||HUF1400-4.JPG||HUF1400-5.JPG||HUF1400-6.JPG||HUF1400-7.JPG||HUF1400-8.JPG||HUF1400-9.JPG||HUF1400-10.JPG | AD7: 229||92867||241||244||48032 | AE7: 588 | AG7: Покупайте датчик давления в шине BH Sens (Huf, Германия) 36106874829 для BMW по выгодным ценам | Большой выбор датчиков давления в шине | Осуществляем доставку на всей территории РФ
A8: 302534 | B8: 1 | C8: 8253 | D8: 20 | E8: 36106877937 | F8: =VLOOKUP(E8,Лист1!A1:A306,1,FALSE) -> 36106877937 | G8: Датчик давления в шине для BMW 36106877937 Оригинал | H8: Купить по низкой цене оригинальный датчик давления в шинах для 36106877937 для BMW с доставкой по Москве или России. | I8: 7500 | J8: Германия | K8: 30 | L8: dk-datchik-davlenia-v-shinah-36106877937-150 | M8: <p>Датчик давления в шинах, номер по каталогу 36106877937, передает сигналы с помощью радиоканала. Рабочая частота - 433МГц. Компания производитель автомобиля BMW. Страна производства - Германия. Устройства предназначены для установки в колеса автомобилей, выпускаемых концерном BMW.</p><p></p><p> При условии установки на специализированных СТО, срок службы устройства составляет до 7 лет.</p><p>Конструктивные особенности данного датчика гарантируют его полную совместимость с системами авто концерна BMW. Датчик поставляется в комплекте с ниппелем, что заметно облегчает установку и не требует покупки дополнительных деталей. Материал ниппеля - металл. После установки датчик 36106877937 требует привязки к авто. Привязка производится по методике <a href="https://alltpms.ru/katalog/privyazka/privyazka-4">«Автоматизированная привязка»</a> (Карточка привязки).</p> | N8: 93 | O8: /market/A4104.jpg | P8: Датчик давления в шине для BMW 36106877937 Оригинал | Q8: Датчик давления в шине для BMW 36106877937 Оригинал | R8: Доставка от 1 шт. без предоплаты, Гарантия 2 года | S8: 0 | T8: 0 | U8: 36106877937-150 | V8: 5054208002071 | W8: 622 | X8: BMW | Y8: 433 | Z8: yes | AA8: Clamp-in | AB8: A0009054104, 36106872774, 36106872803, 36106876955, 36106876957, 36106876957, 36106887147, A0009052102, A0009057205, 3057, A0009058706, 28238, S180211005Z, ECR0280, RDE077V21, RDE035V21, 9014-3057, 9015-3057, 1210-3057, 2210-3057, 2200-3057, 1400-3057, 1401-3057, 4040-3057, 4041-3057, 590914-3057, 590918-3057, 1900-28238, 2901-28238, 4040-28238, 4041-28238, 1400-28238, 1401-28238, 590914-28238, 590918-28238, 3057PFR, 3057PFM, 3057PVM, 28238PVM, 28238PFR, 4040-RDE077, 4041-RDE077, RDE077PVM, RDE077PFR, RDE077PVM, RDE077PFR | AC8: 36106877937-1.JPG||36106877937-2.JPG||36106877937-3.JPG||36106877937-4.JPG||36106877937-5.JPG||36106877937-6.JPG||36106877937-7.JPG||36106877937-8.JPG||36106877937-9.JPG||36106877937-10.JPG | AD8: 229||92867||241||244||48032 | AE8: 588 | AF8: BMW BH Sens ( Huf ) 36106877937 A0009054104, 36106872774, 36106872803, 36106876955, 36106876957, 36106876957, 36106887147, A0009052102, A0009057205, 3057, A0009058706, 28238, S180211005Z, ECR0280, RDE077V21, RDE035V21, 9014-3057, 9015-3057, 1210-3057, 2210-3057, 2200-3057, 1400-3057, 1401-3057, 4040-3057, 4041-3057, 590914-3057, 590918-3057, 1900-28238, 2901-28238, 4040-28238, 4041-28238, 1400-28238, 1401-28238, 590914-28238, 590918-28238, 3057PFR, 3057PFM, 3057PVM, 28238PVM, 28238PFR, 4040-RDE077, 4041-RDE077, RDE077PVM, RDE077PFR, RDE077PVM, RDE077PFR A0009054104, 36106872774, 36106872803, 36106876955, 36106876957, 36106876957, 36106887147, A0009052102, A0009057205, 3057, A0009058706, 28238, S180211005Z, ECR0280, RDE077V21, RDE035V21, 90143057, 90153057, 12103057, 22103057, 22003057, 14003057, 14013057, 40403057, 40413057, 5909143057, 5909183057, 190028238, 290128238, 404028238, 404128238, 140028238, 140128238, 59091428238, 59091828238, 3057PFR, 3057PFM, 3057PVM, 28238PVM, 28238PFR, 4040RDE077, 4041RDE077, RDE077PVM, RDE077PFR, RDE077PVM, RDE077PFR Оригинал | AG8: Купить оригинальный датчик давления в шине для BMW 36106877937 в Москве с доставкой. Цена от производителя. Большой выбор датчиков. Гарантия.
A9: 302535 | B9: 1 | C9: 8253 | D9: 20 | E9: 36106877937 | F9: =VLOOKUP(E9,Лист1!A1:A306,1,FALSE) -> 36106877937 | G9: Датчик давления в шине BH Sens ( Huf ) 36106877937 для BMW (Black Edition) | H9: Покупайте датчик давления в шине BH Sens ( Huf ) 36106877937 для BMW (Black Edition) по выгодным ценам | Большой выбор датчиков давления в шине | Осуществляем доставку на всей территории РФ | I9: 5000 | J9: Германия | K9: 30 | L9: dk-datchik-davlenia-v-shinah-36106877937b-146n | M9: <p>Датчик давления в шинах, номер по каталогу 36106877937, передает сигналы с помощью радиоканала. Рабочая частота - 433МГц. Компания производитель <a href="https://alltpms.ru/proizvoditeli-sistem-tpms/beru"> BH Sens ( Huf ) </a>. Страна производства - Германия. Устройства предназначены для установки в колеса автомобилей, выпускаемых концерном BMW.</p><p></p><p> При условии установки на специализированных СТО, срок службы устройства составляет до 7 лет.</p><p>Конструктивные особенности данного датчика гарантируют его полную совместимость с системами авто концерна BMW. Датчик поставляется в комплекте с ниппелем, что заметно облегчает установку и не требует покупки дополнительных деталей. Материал ниппеля - металл. После установки датчик 36106877937 требует привязки к авто. Привязка производится по методике <a href="https://alltpms.ru/katalog/privyazka/privyazka-4">«Автоматизированная привязка»</a> (Карточка привязки).</p> | N9: 91 | O9: /market/RDE077B.jpg | P9: Датчик давления в шине BH Sens ( Huf ) 36106877937 для BMW (Black Edition) | Q9: Датчик давления в шине BH Sens ( Huf ) 36106877937 для BMW (Black Edition) | R9: Доставка от 1 шт. без предоплаты, Гарантия 2 года | S9: 0 | T9: 0 | U9: 36106877937b-146n | V9: 5054208002072 | W9: 622 | X9: BMW | Y9: 433 | Z9: no | AA9: Clamp-in | AB9: A0009054104, 36106872774, 36106872803, 36106876955, 36106876957, 36106876957, 36106887147, A0009052102, A0009057205, 3057, A0009058706, 28238, S180211005Z, ECR0280, RDE077V21, RDE035V21, 9014-3057, 9015-3057, 1210-3057, 2210-3057, 2200-3057, 1400-3057, 1401-3057, 4040-3057, 4041-3057, 590914-3057, 590918-3057, 1900-28238, 2901-28238, 4040-28238, 4041-28238, 1400-28238, 1401-28238, 590914-28238, 590918-28238, 3057PFR, 3057PFM, 3057PVM, 28238PVM, 28238PFR, 4040-RDE077, 4041-RDE077, RDE077PVM, RDE077PFR, RDE077PVM, RDE077PFR | AC9: RDE077V21_B-1.JPG||RDE077V21_B-2.JPG||RDE077V21_B-3.JPG||RDE077V21_B-4.JPG||RDE077V21_B-5.JPG||RDE077V21_B-6.JPG||RDE077V21_B-7.JPG||RDE077V21_B-8.JPG||RDE077V21_B-9.JPG||RDE077V21_B-10.JPG | AD9: 229||92867||241||244||48032 | AE9: 588 | AG9: Покупайте датчик давления в шине BH Sens ( Huf ) 36106877937 для BMW (Black Edition) по выгодным ценам | Большой выбор датчиков давления в шине | Осуществляем доставку на всей территории РФ
A10: 302536 | B10: 1 | C10: 8253 | D10: 20 | E10: 36106877937 | F10: =VLOOKUP(E10,Лист1!A1:A306,1,FALSE) -> 36106877937 | G10: Датчик давления в шине BH Sens ( Huf, Германия) 36106877937 для BMW (Black Edition) | H10: Покупайте датчик давления в шине BH Sens ( Huf, Германия) 36106877937 для BMW (Black Edition) по выгодным ценам | Большой выбор датчиков давления в шине | Осуществляем доставку на всей территории РФ | I10: 3750 | J10: Германия | K10: 30 | L10: dk-datchik-davlenia-v-shinah-36106877937b-1477 | M10: <p>Датчик давления в шинах, номер по каталогу 36106877937, передает сигналы с помощью радиоканала. Рабочая частота - 433МГц. Компания производитель <a href="https://alltpms.ru/proizvoditeli-sistem-tpms/beru"> BH Sens ( Huf ) </a>. Страна производства - Германия. Устройства предназначены для установки в колеса автомобилей, выпускаемых концерном BMW.</p><p></p><p> При условии установки на специализированных СТО, срок службы устройства составляет до 7 лет.</p><p>Конструктивные особенности данного датчика гарантируют его полную совместимость с системами авто концерна BMW. Датчик поставляется в комплекте с ниппелем, что заметно облегчает установку и не требует покупки дополнительных деталей. Материал ниппеля - металл. После установки датчик 36106877937 требует привязки к авто. Привязка производится по методике <a href="https://alltpms.ru/katalog/privyazka/privyazka-4">«Автоматизированная привязка»</a> (Карточка привязки).</p> | N10: 92 | O10: /market/HUF1410B.jpg | P10: Датчик давления в шине BH Sens ( Huf ) 36106877937 для BMW (Black Edition) | Q10: Датчик давления в шине BH Sens ( Huf ) 36106877937 для BMW (Black Edition) | R10: Доставка от 1 шт. без предоплаты, Гарантия 2 года | S10: 0 | T10: 1 | U10: 36106877937b-1477 | V10: 5054208002073 | W10: 622 | X10: BMW | Y10: 433 | Z10: no | AA10: Clamp-in | AB10: A0009054104, 36106872774, 36106872803, 36106876955, 36106876957, 36106876957, 36106887147, A0009052102, A0009057205, 3057, A0009058706, 28238, S180211005Z, ECR0280, RDE077V21, RDE035V21, 9014-3057, 9015-3057, 1210-3057, 2210-3057, 2200-3057, 1400-3057, 1401-3057, 4040-3057, 4041-3057, 590914-3057, 590918-3057, 1900-28238, 2901-28238, 4040-28238, 4041-28238, 1400-28238, 1401-28238, 590914-28238, 590918-28238, 3057PFR, 3057PFM, 3057PVM, 28238PVM, 28238PFR, 4040-RDE077, 4041-RDE077, RDE077PVM, RDE077PFR, RDE077PVM, RDE077PFR | AC10: HUF1400_B-1.JPG||HUF1400_B-2.JPG||HUF1400_B-3.JPG||HUF1400_B-4.JPG||HUF1400_B-5.JPG||HUF1400_B-6.JPG||HUF1400_B-7.JPG||HUF1400_B-8.JPG||HUF1400_B-9.JPG||HUF1400_B-10.JPG | AD10: 229||92867||241||244||48032 | AE10: 588 | AG10: Покупайте датчик давления в шине BH Sens ( Huf, Германия) 36106877937 для BMW (Black Edition) по выгодным ценам | Большой выбор датчиков давления в шине | Осуществляем доставку на всей территории РФ
A11: 302537 | B11: 1 | C11: 8253 | D11: 20 | E11: 36106877937 | F11: =VLOOKUP(E11,Лист1!A1:A306,1,FALSE) -> 36106877937 | G11: Датчик давления в шине BH Sens ( Huf ) 36106877937 для BMW | H11: Покупайте датчик давления в шине BH Sens ( Huf ) 36106877937 для BMW по выгодным ценам | Большой выбор датчиков давления в шине | Осуществляем доставку на всей территории РФ | I11: 4500 | J11: Германия | K11: 30 | L11: dk-datchik-davlenia-v-shinah-36106877937-146 | M11: <p>Датчик давления в шинах, номер по каталогу 36106877937, передает сигналы с помощью радиоканала. Рабочая частота - 433МГц. Компания производитель <a href="https://alltpms.ru/proizvoditeli-sistem-tpms/beru"> BH Sens ( Huf ) </a>. Страна производства - Германия. Устройства предназначены для установки в колеса автомобилей, выпускаемых концерном BMW.</p><p></p><p> При условии установки на специализированных СТО, срок службы устройства составляет до 7 лет.</p><p>Конструктивные особенности данного датчика гарантируют его полную совместимость с системами авто концерна BMW. Датчик поставляется в комплекте с ниппелем, что заметно облегчает установку и не требует покупки дополнительных деталей. Материал ниппеля - металл. После установки датчик 36106877937 требует привязки к авто. Привязка производится по методике <a href="https://alltpms.ru/katalog/privyazka/privyazka-4">«Автоматизированная привязка»</a> (Карточка привязки).</p> | N11: 95 | O11: /market/RDE077.jpg | P11: Датчик давления в шине BH Sens ( Huf ) 36106877937 для BMW | Q11: Датчик давления в шине BH Sens ( Huf ) 36106877937 для BMW | R11: Доставка от 1 шт. без предоплаты, Гарантия 2 года | S11: 0 | T11: 0 | U11: 36106877937-146 | V11: 5054208002074 | W11: 622 | X11: BMW | Y11: 433 | Z11: no | AA11: Clamp-in | AB11: A0009054104, 36106872774, 36106872803, 36106876955, 36106876957, 36106876957, 36106887147, A0009052102, A0009057205, 3057, A0009058706, 28238, S180211005Z, ECR0280, RDE077V21, RDE035V21, 9014-3057, 9015-3057, 1210-3057, 2210-3057, 2200-3057, 1400-3057, 1401-3057, 4040-3057, 4041-3057, 590914-3057, 590918-3057, 1900-28238, 2901-28238, 4040-28238, 4041-28238, 1400-28238, 1401-28238, 590914-28238, 590918-28238, 3057PFR, 3057PFM, 3057PVM, 28238PVM, 28238PFR, 4040-RDE077, 4041-RDE077, RDE077PVM, RDE077PFR, RDE077PVM, RDE077PFR | AC11: RDE077V21-1.JPG||RDE077V21-2.JPG||RDE077V21-3.JPG||RDE077V21-4.JPG||RDE077V21-5.JPG||RDE077V21-6.JPG||RDE077V21-7.JPG||RDE077V21-8.JPG||RDE077V21-9.JPG||RDE077V21-10.JPG | AD11: 229||92867||241||244||48032 | AE11: 588 | AG11: Покупайте датчик давления в шине BH Sens ( Huf ) 36106877937 для BMW по выгодным ценам | Большой выбор датчиков давления в шине | Осуществляем доставку на всей территории РФ
A12: 302538 | B12: 1 | C12: 8253 | D12: 20 | E12: 36106877937 | F12: =VLOOKUP(E12,Лист1!A1:A306,1,FALSE) -> 36106877937 | G12: Датчик давления в шине BH Sens ( Huf ) 36106877937 для BMW (БМВ) | H12: Покупайте датчик давления в шине BH Sens ( Huf ) 36106877937 для BMW (БМВ) по выгодным ценам | Большой выбор датчиков давления в шине | Осуществляем доставку на всей территории РФ | I12: 3250 | J12: Германия | K12: 30 | L12: dk-datchik-davlenia-v-shinah-36106877937-146n | M12: <p>Датчик TPMS производства компании <a href="https://alltpms.ru/proizvoditeli-sistem-tpms/beru"> BH Sens ( Huf ) </a>. Страна изготовления - Германия. Номер по каталогу 36106877937. Датчик специально разработан для автомобилей BMW.</p><p></p><p>В случае правильной эксплуатации срок службы устройства может достигать 8 лет. Данный показатель варьируется в достаточно широких пределах и зависит от условий эксплуатации автомобиля.</p><p>Выпускаемый компанией <a href="https://alltpms.ru/proizvoditeli-sistem-tpms/beru"> BH Sens ( Huf ) </a> Германия, датчик номер 36106877937 устанавливается на автомобили, производства BMW. Покупатель получает полный комплект для установки. Привязка датчика к автомобилю выполняется по методу <a href="https://alltpms.ru/katalog/privyazka/privyazka-4">«Автоматизированная привязка»</a> (Карточка привязки).</p> | N12: 94 | O12: /market/HUF1410.jpg | P12: Датчик давления в шине BH Sens ( Huf ) 36106877937 для BMW | Q12: Датчик давления в шине BH Sens ( Huf ) 36106877937 для BMW | R12: Доставка от 1 шт. без предоплаты, Гарантия 2 года | S12: 0 | T12: 1 | U12: 36106877937-146n | V12: 5054208002075 | W12: 622 | X12: BMW | Y12: 433 | Z12: no | AA12: Clamp-in | AB12: A0009054104, 36106872774, 36106872803, 36106876955, 36106876957, 36106876957, 36106887147, A0009052102, A0009057205, 3057, A0009058706, 28238, S180211005Z, ECR0280, RDE077V21, RDE035V21, 9014-3057, 9015-3057, 1210-3057, 2210-3057, 2200-3057, 1400-3057, 1401-3057, 4040-3057, 4041-3057, 590914-3057, 590918-3057, 1900-28238, 2901-28238, 4040-28238, 4041-28238, 1400-28238, 1401-28238, 590914-28238, 590918-28238, 3057PFR, 3057PFM, 3057PVM, 28238PVM, 28238PFR, 4040-RDE077, 4041-RDE077, RDE077PVM, RDE077PFR, RDE077PVM, RDE077PFR | AC12: HUF1400-1.JPG||HUF1400-2.JPG||HUF1400-3.JPG||HUF1400-4.JPG||HUF1400-5.JPG||HUF1400-6.JPG||HUF1400-7.JPG||HUF1400-8.JPG||HUF1400-9.JPG||HUF1400-10.JPG | AD12: 229||92867||241||244||48032 | AE12: 588 | AG12: Покупайте датчик давления в шине BH Sens ( Huf ) 36106877937 для BMW (БМВ) по выгодным ценам | Большой выбор датчиков давления в шине | Осуществляем доставку на всей территории РФ
A13: 302539 | B13: 1 | C13: 8253 | D13: 20 | E13: 36106881890 | F13: =VLOOKUP(E13,Лист1!A1:A306,1,FALSE) -> 36106881890 | G13: Датчик давления в шине для BMW 36106881890 Оригинал | H13: Купить по низкой цене оригинальный датчик давления в шинах для BMW 36106881890 с доставкой по Москве или России. | I13: 8250 | J13: Франция | K13: 30 | L13: dk-datchik-davlenia-v-shinah-36106856209-319 | M13: <p>Датчик TPMS для автомобилей производства компании BMW. Страна производства - Франция. Каталожный номер детали 36106881890. Датчик применяется в автомобилях, производства BMW.</p><p></p><p> При нормальных условиях эксплуатации устройство прослужит до 8 лет.</p><p>Данный датчик, производства компании BMW Франция номер 36106881890 рассчитан на установку в колеса легковых автомобилей BMW. Датчик продается в комплекте со штуцером, т.е. покупатель получает полный набор деталей для установки. Материал штуцера - металл. После установки датчика необходимо осуществить его привязку к системе авто. Для этого используется метод <a href="https://alltpms.ru/katalog/privyazka/privyazka-4">«Автоматизированная привязка»</a> (Карточка привязки).</p> | N13: 87 | O13: /market/36106881890.jpg | P13: Датчик давления в шине для BMW 36106881890 Оригинал | Q13: Датчик давления в шине для BMW 36106881890 Оригинал | R13: Доставка от 1 шт. без предоплаты, Гарантия 2 года | S13: 0 | T13: 0 | U13: 36106856209-319 | V13: 5054208002076 | W13: 180 | X13: BMW | Y13: 433 | Z13: yes | AA13: Clamp-in | AB13: 36106855539, 36106856209, 36106858887, 36106858888, 4043, A2C9743250080, A2C97432500, A2C97432501, A2C97432502, S180052056, S180052056Z, S180211011Z, S180211001Z, ECR0050, RDE027V21, 9014-4043, 9015-4043, 1210-4043, 2210-4043, 2200-4043, 1400-4043, 1401-4043, 4040-4043, 4041-4043, 590914-4043, 590918-4043, 4043PFR, 4043PFM, 4043PVM, 4040-RDE027, 4041-RDE027, RDE027PVM, RDE027PFR, RDE027PVM, RDE027PFR | AC13: 36106881890-1.JPG||36106881890-2.JPG||36106881890-3.JPG||36106881890-4.JPG||36106881890-5.JPG||36106881890-6.JPG||36106881890-7.JPG||36106881890-8.JPG||36106881890-9.JPG||36106881890-10.JPG | AD13: 226||48029 | AE13: 588 | AF13: BMW Continental ( VDO ) 36106881890 36106855539, 36106856209, 36106858887, 36106858888, 4043, A2C9743250080, A2C97432500, A2C97432501, A2C97432502, S180052056, S180052056Z, S180211011Z, S180211001Z, ECR0050, RDE027V21, 9014-4043, 9015-4043, 1210-4043, 2210-4043, 2200-4043, 1400-4043, 1401-4043, 4040-4043, 4041-4043, 590914-4043, 590918-4043, 4043PFR, 4043PFM, 4043PVM, 4040-RDE027, 4041-RDE027, RDE027PVM, RDE027PFR, RDE027PVM, RDE027PFR 36106855539, 36106856209, 36106858887, 36106858888, 4043, A2C9743250080, A2C97432500, A2C97432501, A2C97432502, S180052056, S180052056Z, S180211011Z, S180211001Z, ECR0050, RDE027V21, 90144043, 90154043, 12104043, 22104043, 22004043, 14004043, 14014043, 40404043, 40414043, 5909144043, 5909184043, 4043PFR, 4043PFM, 4043PVM, 4040RDE027, 4041RDE027, RDE027PVM, RDE027PFR, RDE027PVM, RDE027PFR Оригинал | AG13: Купить оригинальный датчик давления в шине для BMW 36106881890 в Москве с доставкой. Цена от производителя. Большой выбор датчиков. Гарантия.
A14: 302540 | B14: 1 | C14: 8253 | D14: 20 | E14: 36106881890 | F14: =VLOOKUP(E14,Лист1!A1:A306,1,FALSE) -> 36106881890 | G14: Датчик давления в шине BH Sens ( Huf ) 36106881890 для BMW (Black Edition) | H14: Покупайте датчик давления в шине BH Sens ( Huf ) 36106881890 для BMW (Black Edition) по выгодным ценам | Большой выбор датчиков давления в шине | Осуществляем доставку на всей территории РФ | I14: 3750 | J14: Германия | K14: 30 | L14: dk-datchik-davlenia-v-shinah-36106856209b-30 | M14: <p>Датчик, каталожный номер 36106881890. Передача данных производится посредством радиосигнала. Частота работы - 433МГц. Производитель – компания <a href="https://alltpms.ru/proizvoditeli-sistem-tpms/beru"> BH Sens ( Huf ) </a>. Страна-производитель - Германия.</p><p> Срок службы устройства варьируется и может достигать 7 лет. Данный показатель во многом зависит от интенсивности использования авто и условий его эксплуатации.</p><p> Конструктивные особенности датчика позволяют использовать его на большинстве марок авто производства BMW. Комплект поставки – датчик и ниппель. Материал ниппеля - металл. Комплект полностью готов к установке. Данный датчик, номер 36106881890 требует привязки к системе автомобиля. Для этого используется процедура <a href="https://alltpms.ru/katalog/privyazka/privyazka-4">«Автоматизированная привязка»</a> (Карточка привязки).</p> | N14: 88 | O14: /market/HUF1410B.jpg | P14: Датчик давления в шине BH Sens ( Huf ) 36106881890 для BMW (Black Edition) | Q14: Датчик давления в шине BH Sens ( Huf ) 36106881890 для BMW (Black Edition) | R14: Доставка от 1 шт. без предоплаты, Гарантия 2 года | S14: 0 | T14: 1 | U14: 36106856209b-30 | V14: 5054208002077 | W14: 622 | X14: BMW | Y14: 433 | Z14: no | AA14: Clamp-in | AB14: 36106855539, 36106856209, 36106858887, 36106858888, 4043, A2C9743250080, A2C97432500, A2C97432501, A2C97432502, S180052056, S180052056Z, S180211011Z, S180211001Z, ECR0050, RDE027V21, 9014-4043, 9015-4043, 1210-4043, 2210-4043, 2200-4043, 1400-4043, 1401-4043, 4040-4043, 4041-4043, 590914-4043, 590918-4043, 4043PFR, 4043PFM, 4043PVM, 4040-RDE027, 4041-RDE027, RDE027PVM, RDE027PFR, RDE027PVM, RDE027PFR | AC14: HUF1400_B-1.JPG||HUF1400_B-2.JPG||HUF1400_B-3.JPG||HUF1400_B-4.JPG||HUF1400_B-5.JPG||HUF1400_B-6.JPG||HUF1400_B-7.JPG||HUF1400_B-8.JPG||HUF1400_B-9.JPG||HUF1400_B-10.JPG | AD14: 226||48029 | AE14: 588 | AG14: Покупайте датчик давления в шине BH Sens ( Huf ) 36106881890 для BMW (Black Edition) по выгодным ценам | Большой выбор датчиков давления в шине | Осуществляем доставку на всей территории РФ
A15: 302541 | B15: 1 | C15: 8253 | D15: 20 | E15: 36106881890 | F15: =VLOOKUP(E15,Лист1!A1:A306,1,FALSE) -> 36106881890 | G15: Датчик давления в шине Continental ( VDO ) 36106881890 для BMW | H15: Купить по низкой цене датчик давления в шинах Continental ( VDO ) 36106881890 для BMW с доставкой по Москве или России. | I15: 4500 | J15: Франция | K15: 30 | L15: dk-datchik-davlenia-v-shinah-36106856209-3190 | M15: <p>Датчик 36106881890 контроля давления в шинах. Передача данных реализована по радиоканалу. Используемая частота - 433МГц. Производит устройства компания <a href="https://alltpms.ru/proizvoditeli-sistem-tpms/vdo"> Continental ( VDO ) </a>. Страна производства - Франция.</p><p> Датчики устанавливаются в автомобили, выпускаемые концерном BMW.</p><p></p><p> При условии правильной установки и эксплуатации, срок работы составит 6 лет и более. Срок варьируется в зависимости от интенсивности эксплуатации, частоты и продолжительности поездок.</p><p>Данный датчик 36106881890 сконструирован в расчете на установку в автомобили концерна BMW. В продажу поступают готовые комплекты. В комплект входит сам датчик и ниппель. После установки датчик необходимо активировать. Процесс выполняется с использованием методики <a href="https://alltpms.ru/katalog/privyazka/privyazka-4">«Автоматизированная привязка»</a> (Карточка привязки).</p> | N15: 90 | O15: /market/TG1CEVO.jpg | P15: Датчик давления в шине Continental ( VDO ) 36106881890 для BMW | Q15: Датчик давления в шине Continental ( VDO ) 36106881890 для BMW | R15: Доставка от 1 шт. без предоплаты, Гарантия 2 года | S15: 0 | T15: 0 | U15: 36106856209-3190 | V15: 5054208002078 | W15: 180 | X15: BMW | Y15: 433 | Z15: no | AA15: Clamp-in | AB15: 36106855539, 36106856209, 36106858887, 36106858888, 4043, A2C9743250080, A2C97432500, A2C97432501, A2C97432502, S180052056, S180052056Z, S180211011Z, S180211001Z, ECR0050, RDE027V21, 9014-4043, 9015-4043, 1210-4043, 2210-4043, 2200-4043, 1400-4043, 1401-4043, 4040-4043, 4041-4043, 590914-4043, 590918-4043, 4043PFR, 4043PFM, 4043PVM, 4040-RDE027, 4041-RDE027, RDE027PVM, RDE027PFR, RDE027PVM, RDE027PFR | AC15: 36106881890-VDO-1.JPG||36106881890-VDO-2.JPG||36106881890-VDO-3.JPG||36106881890-VDO-4.JPG||36106881890-VDO-5.JPG||36106881890-VDO-6.JPG||36106881890-VDO-7.JPG||36106881890-VDO-8.JPG||36106881890-VDO-9.JPG||36106881890-VDO-10.JPG | AD15: 226||48029 | AE15: 588 | AF15: BMW Continental ( VDO ) 36106881890 36106855539, 36106856209, 36106858887, 36106858888, 4043, A2C9743250080, A2C97432500, A2C97432501, A2C97432502, S180052056, S180052056Z, S180211011Z, S180211001Z, ECR0050, RDE027V21, 9014-4043, 9015-4043, 1210-4043, 2210-4043, 2200-4043, 1400-4043, 1401-4043, 4040-4043, 4041-4043, 590914-4043, 590918-4043, 4043PFR, 4043PFM, 4043PVM, 4040-RDE027, 4041-RDE027, RDE027PVM, RDE027PFR, RDE027PVM, RDE027PFR 36106855539, 36106856209, 36106858887, 36106858888, 4043, A2C9743250080, A2C97432500, A2C97432501, A2C97432502, S180052056, S180052056Z, S180211011Z, S180211001Z, ECR0050, RDE027V21, 90144043, 90154043, 12104043, 22104043, 22004043, 14004043, 14014043, 40404043, 40414043, 5909144043, 5909184043, 4043PFR, 4043PFM, 4043PVM, 4040RDE027, 4041RDE027, RDE027PVM, RDE027PFR, RDE027PVM, RDE027PFR | AG15: Купить датчик давления в шине Continental ( VDO ) 36106881890 для BMW в Москве с доставкой. Цена от производителя. Большой выбор датчиков. Гарантия.
A16: 302542 | B16: 1 | C16: 8253 | D16: 20 | E16: 36106881890 | F16: =VLOOKUP(E16,Лист1!A1:A306,1,FALSE) -> 36106881890 | G16: Датчик давления в шине BH Sens ( Huf ) 36106881890 для BMW | H16: Покупайте датчик давления в шине BH Sens ( Huf ) 36106881890 для BMW по выгодным ценам | Большой выбор датчиков давления в шине | Осуществляем доставку на всей территории РФ | I16: 3250 | J16: Германия | K16: 30 | L16: dk-datchik-davlenia-v-shinah-36106856209-30 | M16: <p>Датчик, номер по каталогу запчастей 36106881890. Предназначен для контроля давления в шинах. Передача данных осуществляется посредством радиосигнала на частоте 433МГц. Компания производитель датчика - <a href="https://alltpms.ru/proizvoditeli-sistem-tpms/beru"> BH Sens ( Huf ) </a>. Место производства - Германия.</p><p>Правильно установленный датчик гарантировано проработает 7 лет. В каждом конкретном случае срок службы может изменяться. Он зависит от условий эксплуатации, длительности поездок, их частоты.</p><p>Предназначенный для установки в колеса автомобилей большинства моделей концерна BMW, датчик поставляется в комплекте с ниппелем. Покупатель получает комплектное устройство. После установки датчик 36106881890 активируется, используется метод <a href="https://alltpms.ru/katalog/privyazka/privyazka-4">«Автоматизированная привязка»</a> (Карточка привязки).</p> | N16: 89 | O16: /market/HUF1410.jpg | P16: Датчик давления в шине BH Sens ( Huf ) 36106881890 для BMW | Q16: Датчик давления в шине BH Sens ( Huf ) 36106881890 для BMW | R16: Доставка от 1 шт. без предоплаты, Гарантия 2 года | S16: 0 | T16: 1 | U16: 36106856209-30 | V16: 5054208002079 | W16: 622 | X16: BMW | Y16: 433 | Z16: no | AA16: Clamp-in | AB16: 36106855539, 36106856209, 36106858887, 36106858888, 4043, A2C9743250080, A2C97432500, A2C97432501, A2C97432502, S180052056, S180052056Z, S180211011Z, S180211001Z, ECR0050, RDE027V21, 9014-4043, 9015-4043, 1210-4043, 2210-4043, 2200-4043, 1400-4043, 1401-4043, 4040-4043, 4041-4043, 590914-4043, 590918-4043, 4043PFR, 4043PFM, 4043PVM, 4040-RDE027, 4041-RDE027, RDE027PVM, RDE027PFR, RDE027PVM, RDE027PFR | AC16: HUF1400-1.JPG||HUF1400-2.JPG||HUF1400-3.JPG||HUF1400-4.JPG||HUF1400-5.JPG||HUF1400-6.JPG||HUF1400-7.JPG||HUF1400-8.JPG||HUF1400-9.JPG||HUF1400-10.JPG | AD16: 226||48029 | AE16: 588 | AG16: Покупайте датчик давления в шине BH Sens ( Huf ) 36106881890 для BMW по выгодным ценам | Большой выбор датчиков давления в шине | Осуществляем доставку на всей территории РФ
A17: 302543 | B17: 1 | C17: 8253 | D17: 20 | E17: 36106887147 | F17: =VLOOKUP(E17,Лист1!A1:A306,1,FALSE) -> 36106887147 | G17: Датчик давления в шине для BMW 36106887147 Оригинал | H17: Купить по низкой цене оригинальный датчик давления в шинах для BMW 36106887147 с доставкой по Москве или России. | I17: 7500 | J17: Англия | K17: 30 | L17: dk-datchik-davlenia-v-shinah-36106872803-319 | M17: <p>Датчик давления в шинах, номер по каталогу 36106887147, передает сигналы с помощью радиоканала. Рабочая частота - 433МГц. Компания производитель автомобиля BMW. Страна производства - Англия. Устройства предназначены для установки в колеса автомобилей, выпускаемых концерном BMW.</p><p></p><p> При условии установки на специализированных СТО, срок службы устройства составляет до 7 лет.</p><p>Конструктивные особенности данного датчика гарантируют его полную совместимость с системами авто концерна BMW. Датчик поставляется в комплекте с ниппелем, что заметно облегчает установку и не требует покупки дополнительных деталей. Материал ниппеля - металл. После установки датчик 36106887147 требует привязки к авто. Привязка производится по методике <a href="https://alltpms.ru/katalog/privyazka/privyazka-4">«Автоматизированная привязка»</a> (Карточка привязки).</p> | N17: 97 | O17: /market/A2102.jpg | P17: Датчик давления в шине для BMW 36106887147 Оригинал | Q17: Датчик давления в шине для BMW 36106887147 Оригинал | R17: Доставка от 1 шт. без предоплаты, Гарантия 2 года | S17: 0 | T17: 0 | U17: 36106872803-319 | V17: 5054208002080 | W17: 625 | X17: BMW | Y17: 433 | Z17: yes | AA17: Clamp-in | AB17: 36106872774, 36106872803, 36106876955, 36106876957, 36106876957, 36106877937, A0009052102, A0009057205, A0009054104, 3057, A0009058706, 28238, S180211005Z, ECR0280, RDE077V21, RDE035V21, 9014-3057, 9015-3057, 1210-3057, 2210-3057, 2200-3057, 1400-3057, 1401-3057, 4040-3057, 4041-3057, 590914-3057, 590918-3057, 1900-28238, 2901-28238, 4040-28238, 4041-28238, 1400-28238, 1401-28238, 590914-28238, 590918-28238, 3057PFR, 3057PFM, 3057PVM, 28238PVM, 28238PFR, 4040-RDE077, 4041-RDE077, RDE077PVM, RDE077PFR, RDE077PVM, RDE077PFR | AC17: 36106872803-1.JPG||36106872803-2.JPG||36106872803-3.JPG||36106872803-4.JPG||36106872803-5.JPG||36106872803-6.JPG||36106872803-7.JPG||36106872803-8.JPG||36106872803-9.JPG||36106872803-10.JPG | AD17: 211||48023||92872 | AE17: 588 | AF17: BMW Schrader 36106887147 36106872774, 36106872803, 36106876955, 36106876957, 36106876957, 36106877937, A0009052102, A0009057205, A0009054104, 3057, A0009058706, 28238, S180211005Z, ECR0280, RDE077V21, RDE035V21, 9014-3057, 9015-3057, 1210-3057, 2210-3057, 2200-3057, 1400-3057, 1401-3057, 4040-3057, 4041-3057, 590914-3057, 590918-3057, 1900-28238, 2901-28238, 4040-28238, 4041-28238, 1400-28238, 1401-28238, 590914-28238, 590918-28238, 3057PFR, 3057PFM, 3057PVM, 28238PVM, 28238PFR, 4040-RDE077, 4041-RDE077, RDE077PVM, RDE077PFR, RDE077PVM, RDE077PFR 36106872774, 36106872803, 36106876955, 36106876957, 36106876957, 36106877937, A0009052102, A0009057205, A0009054104, 3057, A0009058706, 28238, S180211005Z, ECR0280, RDE077V21, RDE035V21, 90143057, 90153057, 12103057, 22103057, 22003057, 14003057, 14013057, 40403057, 40413057, 5909143057, 5909183057, 190028238, 290128238, 404028238, 404128238, 140028238, 140128238, 59091428238, 59091828238, 3057PFR, 3057PFM, 3057PVM, 28238PVM, 28238PFR, 4040RDE077, 4041RDE077, RDE077PVM, RDE077PFR, RDE077PVM, RDE077PFR Оригинал | AG17: Купить оригинальный датчик давления в шине для BMW 36106887147 в Москве с доставкой. Цена от производителя. Большой выбор датчиков. Гарантия.
A18: 302544 | B18: 1 | C18: 8253 | D18: 20 | E18: 36106887147 | F18: =VLOOKUP(E18,Лист1!A1:A306,1,FALSE) -> 36106887147 | G18: Датчик давления в шине BH Sens ( Huf ) 36106887147 для BMW (Black Edition) | H18: Покупайте датчик давления в шине BH Sens ( Huf ) 36106887147 для BMW (Black Edition) по выгодным ценам | Большой выбор датчиков давления в шине | Осуществляем доставку на всей территории РФ | I18: 3750 | J18: Германия | K18: 30 | L18: dk-datchik-davlenia-v-shinah-36106872803bb-30 | M18: <p>Датчик TPMS, производства компании <a href="https://alltpms.ru/proizvoditeli-sistem-tpms/beru"> BH Sens ( Huf ) </a>. Страна производства - Германия. Каталожный номер детали 36106887147. Датчик применяется в автомобилях, производства BMW.</p><p></p><p> При нормальных условиях эксплуатации устройство прослужит до 8 лет.</p><p>Данный датчик, производства компании <a href="https://alltpms.ru/proizvoditeli-sistem-tpms/beru"> BH Sens ( Huf ) </a> Германия номер 36106887147 рассчитан на установку в колеса легковых автомобилей BMW. Датчик продается в комплекте со штуцером, т.е. покупатель получает полный набор деталей для установки. Материал штуцера - металл. После установки датчика необходимо осуществить его привязку к системе авто. Для этого используется метод <a href="https://alltpms.ru/katalog/privyazka/privyazka-4">«Автоматизированная привязка»</a> (Карточка привязки).</p> | N18: 96 | O18: /market/HUF1410B.jpg | P18: Датчик давления в шине BH Sens ( Huf ) 36106887147 для BMW (Black Edition) | Q18: Датчик давления в шине BH Sens ( Huf ) 36106887147 для BMW (Black Edition) | R18: Доставка от 1 шт. без предоплаты, Гарантия 2 года | S18: 0 | T18: 1 | U18: 36106872803bb-30 | V18: 5054208002081 | W18: 622 | X18: BMW | Y18: 433 | Z18: no | AA18: Clamp-in | AB18: 36106872774, 36106872803, 36106876955, 36106876957, 36106876957, 36106877937, A0009052102, A0009057205, A0009054104, 3057, A0009058706, 28238, S180211005Z, ECR0280, RDE077V21, RDE035V21, 9014-3057, 9015-3057, 1210-3057, 2210-3057, 2200-3057, 1400-3057, 1401-3057, 4040-3057, 4041-3057, 590914-3057, 590918-3057, 1900-28238, 2901-28238, 4040-28238, 4041-28238, 1400-28238, 1401-28238, 590914-28238, 590918-28238, 3057PFR, 3057PFM, 3057PVM, 28238PVM, 28238PFR, 4040-RDE077, 4041-RDE077, RDE077PVM, RDE077PFR, RDE077PVM, RDE077PFR | AC18: HUF1400_B-1.JPG||HUF1400_B-2.JPG||HUF1400_B-3.JPG||HUF1400_B-4.JPG||HUF1400_B-5.JPG||HUF1400_B-6.JPG||HUF1400_B-7.JPG||HUF1400_B-8.JPG||HUF1400_B-9.JPG||HUF1400_B-10.JPG | AD18: 211||48023||92872 | AE18: 588 | AG18: Покупайте датчик давления в шине BH Sens ( Huf ) 36106887147 для BMW (Black Edition) по выгодным ценам | Большой выбор датчиков давления в шине | Осуществляем доставку на всей территории РФ
A19: 302545 | B19: 1 | C19: 8253 | D19: 20 | E19: 36106887147 | F19: =VLOOKUP(E19,Лист1!A1:A306,1,FALSE) -> 36106887147 | G19: Датчик давления в шине BH Sens ( Huf ) 36106887147 для BMW | H19: Покупайте датчик давления в шине BH Sens ( Huf ) 36106887147 для BMW по выгодным ценам | Большой выбор датчиков давления в шине | Осуществляем доставку на всей территории РФ | I19: 3250 | J19: Германия | K19: 30 | L19: dk-datchik-davlenia-v-shinah-36106872803-30 | M19: <p>Датчик 36106887147 контроля давления в шинах. Передача данных реализована по радиоканалу. Используемая частота - 433МГц. Производит устройства компания <a href="https://alltpms.ru/proizvoditeli-sistem-tpms/beru"> BH Sens ( Huf ) </a>. Страна производства - Германия.</p><p> Датчики устанавливаются в автомобили, выпускаемые концерном BMW.</p><p></p><p> При условии правильной установки и эксплуатации, срок работы составит 6 лет и более. Срок варьируется в зависимости от интенсивности эксплуатации, частоты и продолжительности поездок.</p><p>Данный датчик 36106887147 сконструирован в расчете на установку в автомобили концерна BMW. В продажу поступают готовые комплекты. В комплект входит сам датчик и ниппель. После установки датчик необходимо активировать. Процесс выполняется с использованием методики <a href="https://alltpms.ru/katalog/privyazka/privyazka-4">«Автоматизированная привязка»</a> (Карточка привязки).</p> | N19: 98 | O19: /market/HUF1410.jpg | P19: Датчик давления в шине BH Sens ( Huf ) 36106887147 для BMW | Q19: Датчик давления в шине BH Sens ( Huf ) 36106887147 для BMW | R19: Доставка от 1 шт. без предоплаты, Гарантия 2 года | S19: 0 | T19: 1 | U19: 36106872803-30 | V19: 5054208002082 | W19: 622 | X19: BMW | Y19: 433 | Z19: no | AA19: Clamp-in | AB19: 36106872774, 36106872803, 36106876955, 36106876957, 36106876957, 36106877937, A0009052102, A0009057205, A0009054104, 3057, A0009058706, 28238, S180211005Z, ECR0280, RDE077V21, RDE035V21, 9014-3057, 9015-3057, 1210-3057, 2210-3057, 2200-3057, 1400-3057, 1401-3057, 4040-3057, 4041-3057, 590914-3057, 590918-3057, 1900-28238, 2901-28238, 4040-28238, 4041-28238, 1400-28238, 1401-28238, 590914-28238, 590918-28238, 3057PFR, 3057PFM, 3057PVM, 28238PVM, 28238PFR, 4040-RDE077, 4041-RDE077, RDE077PVM, RDE077PFR, RDE077PVM, RDE077PFR | AC19: HUF1400-1.JPG||HUF1400-2.JPG||HUF1400-3.JPG||HUF1400-4.JPG||HUF1400-5.JPG||HUF1400-6.JPG||HUF1400-7.JPG||HUF1400-8.JPG||HUF1400-9.JPG||HUF1400-10.JPG | AD19: 211||48023||92872 | AE19: 588 | AG19: Покупайте датчик давления в шине BH Sens ( Huf ) 36106887147 для BMW по выгодным ценам | Большой выбор датчиков давления в шине | Осуществляем доставку на всей территории РФ
A20: 302546 | B20: 1 | C20: 8253 | D20: 20 | E20: 36106887147 | F20: =VLOOKUP(E20,Лист1!A1:A306,1,FALSE) -> 36106887147 | G20: Датчик давления в шине Schrader 36106887147 для BMW | H20: Купить по низкой цене датчик давления в шинах Schrader 36106887147 для BMW с доставкой по Москве или России. | I20: 4500 | J20: Англия | K20: 30 | L20: dk-datchik-davlenia-v-shinah-36106872803-21 | M20: <p>Датчик давления в шинах, номер по каталогу 36106887147, передает сигналы с помощью радиоканала. Рабочая частота - 433МГц. Компания производитель <a href="https://alltpms.ru/proizvoditeli-sistem-tpms/schrader"> Schrader </a>. Страна производства - Англия. Устройства предназначены для установки в колеса автомобилей, выпускаемых концерном BMW.</p><p></p><p> При условии установки на специализированных СТО, срок службы устройства составляет до 7 лет.</p><p>Конструктивные особенности данного датчика гарантируют его полную совместимость с системами авто концерна BMW. Датчик поставляется в комплекте с ниппелем, что заметно облегчает установку и не требует покупки дополнительных деталей. Материал ниппеля - металл. После установки датчик 36106887147 требует привязки к авто. Привязка производится по методике <a href="https://alltpms.ru/katalog/privyazka/privyazka-4">«Автоматизированная привязка»</a> (Карточка привязки).</p> | N20: 99 | O20: /market/3057.jpg | P20: Датчик давления в шине Schrader 36106887147 для BMW | Q20: Датчик давления в шине Schrader 36106887147 для BMW | R20: Доставка от 1 шт. без предоплаты, Гарантия 2 года | S20: 0 | T20: 0 | U20: 36106872803-21 | V20: 5054208002083 | W20: 625 | X20: BMW | Y20: 433 | Z20: no | AA20: Clamp-in | AB20: 36106872774, 36106872803, 36106876955, 36106876957, 36106876957, 36106877937, A0009052102, A0009057205, A0009054104, 3057, A0009058706, 28238, S180211005Z, ECR0280, RDE077V21, RDE035V21, 9014-3057, 9015-3057, 1210-3057, 2210-3057, 2200-3057, 1400-3057, 1401-3057, 4040-3057, 4041-3057, 590914-3057, 590918-3057, 1900-28238, 2901-28238, 4040-28238, 4041-28238, 1400-28238, 1401-28238, 590914-28238, 590918-28238, 3057PFR, 3057PFM, 3057PVM, 28238PVM, 28238PFR, 4040-RDE077, 4041-RDE077, RDE077PVM, RDE077PFR, RDE077PVM, RDE077PFR | AC20: 3057-1.JPG||3057-2.JPG||3057-3.JPG||3057-4.JPG||3057-5.JPG||3057-6.JPG||3057-7.JPG||3057-8.JPG||3057-9.JPG||3057-10.JPG | AD20: 211||48023||92872 | AE20: 588 | AF20: BMW Schrader 36106887147 36106872774, 36106872803, 36106876955, 36106876957, 36106876957, 36106877937, A0009052102, A0009057205, A0009054104, 3057, A0009058706, 28238, S180211005Z, ECR0280, RDE077V21, RDE035V21, 9014-3057, 9015-3057, 1210-3057, 2210-3057, 2200-3057, 1400-3057, 1401-3057, 4040-3057, 4041-3057, 590914-3057, 590918-3057, 1900-28238, 2901-28238, 4040-28238, 4041-28238, 1400-28238, 1401-28238, 590914-28238, 590918-28238, 3057PFR, 3057PFM, 3057PVM, 28238PVM, 28238PFR, 4040-RDE077, 4041-RDE077, RDE077PVM, RDE077PFR, RDE077PVM, RDE077PFR 36106872774, 36106872803, 36106876955, 36106876957, 36106876957, 36106877937, A0009052102, A0009057205, A0009054104, 3057, A0009058706, 28238, S180211005Z, ECR0280, RDE077V21, RDE035V21, 90143057, 90153057, 12103057, 22103057, 22003057, 14003057, 14013057, 40403057, 40413057, 5909143057, 5909183057, 190028238, 290128238, 404028238, 404128238, 140028238, 140128238, 59091428238, 59091828238, 3057PFR, 3057PFM, 3057PVM, 28238PVM, 28238PFR, 4040RDE077, 4041RDE077, RDE077PVM, RDE077PFR, RDE077PVM, RDE077PFR | AG20: Купить датчик давления в шине Schrader 36106887147 для BMW в Москве с доставкой. Цена от производителя. Большой выбор датчиков. Гарантия.
A21: 302547 | B21: 1 | C21: 8253 | D21: 20 | E21: 36106890964 | F21: =VLOOKUP(E21,Лист1!A1:A306,1,FALSE) -> 36106890964 | G21: Датчик давления в шине BH Sens ( Huf ) 36106890964 для BMW (Black Edition) | H21: Покупайте датчик давления в шине BH Sens ( Huf ) 36106890964 для BMW (Black Edition) по выгодным ценам | Большой выбор датчиков давления в шине | Осуществляем доставку на всей территории РФ | I21: 4250 | J21: Германия | K21: 30 | L21: dk-datchik-davlenia-v-shinah-36106798872b-32 | M21: <p>Датчик 36106890964 контроля давления в шинах. Передача данных реализована по радиоканалу. Используемая частота - 433МГц. Производит устройства компания <a href="https://alltpms.ru/proizvoditeli-sistem-tpms/beru"> BH Sens ( Huf ) </a>. Страна производства - Германия.</p><p> Датчики устанавливаются в автомобили, выпускаемые концерном BMW.</p><p></p><p> При условии правильной установки и эксплуатации, срок работы составит 6 лет и более. Срок варьируется в зависимости от интенсивности эксплуатации, частоты и продолжительности поездок.</p><p>Данный датчик 36106890964 сконструирован в расчете на установку в автомобили концерна BMW. В продажу поступают готовые комплекты. В комплект входит сам датчик и ниппель. После установки датчик необходимо активировать. Процесс выполняется с использованием методики <a href="https://alltpms.ru/katalog/privyazka/privyazka-4">«Автоматизированная привязка»</a> (Карточка привязки).</p> | N21: 76 | O21: /market/RDE047V21B.jpg | P21: Датчик давления в шине BH Sens ( Huf ) 36106890964 для BMW (Black Edition) | Q21: Датчик давления в шине BH Sens ( Huf ) 36106890964 для BMW (Black Edition) | R21: Доставка от 1 шт. без предоплаты, Гарантия 2 года | S21: 0 | T21: 1 | U21: 36106798872b-32 | V21: 5054208002084 | W21: 622 | X21: BMW | Y21: 433 | Z21: no | AA21: Clamp-in | AB21: 36106798872, 36106874830, 4069, 550-1917, TX-S004L/R, TPS0004L/R, ECR0010, RDE012V21, 9014-4069, 9015-4069, 1210-4069, 2210-4069, 2200-4069, 1400-4069, 1401-4069, 4040-4069, 4041-4069, 590914-4069, 590918-4069, 4069PFR, 4069PFM, 4069PVM, 4040-RDE012, 4041-RDE012, RDE012PVM, RDE012PFR, RDE012PVM, RDE012PFR | AC21: HUF4040_B-1.JPG||HUF4040_B-2.JPG||HUF4040_B-3.JPG||HUF4040_B-4.JPG||HUF4040_B-5.JPG||HUF4040_B-6.JPG||HUF4040_B-7.JPG||HUF4040_B-8.JPG||HUF4040_B-9.JPG||HUF4040_B-10.JPG | AD21: 229||92867||241||244||48032 | AE21: 588 | AG21: Покупайте датчик давления в шине BH Sens ( Huf ) 36106890964 для BMW (Black Edition) по выгодным ценам | Большой выбор датчиков давления в шине | Осуществляем доставку на всей территории РФ
A22: 302548 | B22: 1 | C22: 8253 | D22: 20 | E22: 36106890964 | F22: =VLOOKUP(E22,Лист1!A1:A306,1,FALSE) -> 36106890964 | G22: Датчик давления в шине BH Sens ( Huf, Германия ) 36106890964 для BMW | H22: Покупайте датчик давления в шине BH Sens ( Huf, Германия ) 36106890964 для BMW по выгодным ценам | Большой выбор датчиков давления в шине | Осуществляем доставку на всей территории РФ | I22: 3750 | J22: Германия | K22: 30 | L22: dk-datchik-davlenia-v-shinah-36106798872-32 | M22: <p>Датчик 36106890964 контроля давления в шинах. Передача данных реализована по радиоканалу. Используемая частота - 433МГц. Производит устройства компания <a href="https://alltpms.ru/proizvoditeli-sistem-tpms/beru"> BH Sens ( Huf ) </a>. Страна производства - Германия.</p><p> Датчики устанавливаются в автомобили, выпускаемые концерном BMW.</p><p></p><p> При условии правильной установки и эксплуатации, срок работы составит 6 лет и более. Срок варьируется в зависимости от интенсивности эксплуатации, частоты и продолжительности поездок.</p><p>Данный датчик 36106890964 сконструирован в расчете на установку в автомобили концерна BMW. В продажу поступают готовые комплекты. В комплект входит сам датчик и ниппель. После установки датчик необходимо активировать. Процесс выполняется с использованием методики <a href="https://alltpms.ru/katalog/privyazka/privyazka-4">«Автоматизированная привязка»</a> (Карточка привязки).</p> | N22: 78 | O22: /market/RDE047.jpg | P22: Датчик давления в шине BH Sens ( Huf ) 36106890964 для BMW | Q22: Датчик давления в шине BH Sens ( Huf ) 36106890964 для BMW | R22: Доставка от 1 шт. без предоплаты, Гарантия 2 года | S22: 0 | T22: 1 | U22: 36106798872-32 | V22: 5054208002085 | W22: 622 | X22: BMW | Y22: 433 | Z22: no | AA22: Clamp-in | AB22: 36106798872, 36106874830, 4069, 550-1917, TX-S004L/R, TPS0004L/R, ECR0010, RDE012V21, 9014-4069, 9015-4069, 1210-4069, 2210-4069, 2200-4069, 1400-4069, 1401-4069, 4040-4069, 4041-4069, 590914-4069, 590918-4069, 4069PFR, 4069PFM, 4069PVM, 4040-RDE012, 4041-RDE012, RDE012PVM, RDE012PFR, RDE012PVM, RDE012PFR | AC22: HUF4040-1.JPG||HUF4040-2.JPG||HUF4040-3.JPG||HUF4040-4.JPG||HUF4040-5.JPG||HUF4040-6.JPG||HUF4040-7.JPG||HUF4040-8.JPG||HUF4040-9.JPG||HUF4040-10.JPG | AD22: 229||92867||241||244||48032 | AE22: 588 | AG22: Покупайте датчик давления в шине BH Sens ( Huf, Германия ) 36106890964 для BMW по выгодным ценам | Большой выбор датчиков давления в шине | Осуществляем доставку на всей территории РФ
